<?xml version="1.0"?>
<robot name="bike_training_wheels" xmlns:xacro="http://ros.org/wiki/xacro">

    <xacro:include filename="bike_description.xacro" />

    <link name="left_training_wheel_bar">
        <visual>
            <origin xyz="-0.15 0 0" rpy="0 0 0"/>
            <geometry>
                <box size="0.3 0.03 0.03"/>
            </geometry>
            <material name="grey"/>
        </visual>
        <xacro:chassis_inertial/>
    </link>
    <joint name="left_training_wheel_bar_joint" type="fixed">
        <parent link="base_link"/>
        <child link="left_training_wheel_bar"/>
        <origin xyz="-0.25 0 0" rpy="0 ${1+3.14} -1.5"/>
    </joint>

    <xacro:wheel_macro name="left_training_wheel" radius="0.1"/>
    <joint name="left_training_wheel_joint" type="continuous">
        <parent link="left_training_wheel_bar"/>
        <child link="left_training_wheel"/>
        <origin xyz="-0.3 0 0" rpy="3.14 2.2 0"/>
        <axis xyz="0 0 1"/>
    </joint>

    <link name="right_training_wheel_bar">
        <visual>
            <origin xyz="-0.15 0 0" rpy="0 0 0"/>
            <geometry>
                <box size="0.3 0.03 0.03"/>
            </geometry>
            <material name="grey"/>
        </visual>
        <xacro:chassis_inertial/>
    </link>
    <joint name="right_training_wheel_bar_joint" type="fixed">
        <parent link="base_link"/>
        <child link="right_training_wheel_bar"/>
        <origin xyz="-0.25 0 0" rpy="0 1 1.5"/>
    </joint>

    <xacro:wheel_macro name="right_training_wheel" radius="0.1"/>
    <joint name="right_training_wheel_joint" type="continuous">
        <parent link="right_training_wheel_bar"/>
        <child link="right_training_wheel"/>
        <origin xyz="-0.3 0 0" rpy="3.14 2.2 0"/>
        <axis xyz="0 0 1"/>
    </joint>

    <gazebo>
        <plugin name="gazebo_ros_joint_state_publisher" filename="libgazebo_ros_joint_state_publisher.so">
            <update_rate>100</update_rate>
            <joint_name>left_training_wheel_joint</joint_name>
            <joint_name>right_training_wheel_joint</joint_name>
        </plugin>
    </gazebo>

    <gazebo reference="left_training_wheel_bar">
        <material>Gazebo/Green</material>
    </gazebo>
    <gazebo reference="left_training_wheel">
        <material>Gazebo/Green</material>
    </gazebo>
    <gazebo reference="right_training_wheel_bar">
        <material>Gazebo/Green</material>
    </gazebo>
    <gazebo reference="right_training_wheel">
        <material>Gazebo/Green</material>
    </gazebo>
</robot>