<?xml version="1.0"?>
<robot name="bike" xmlns:xacro="http://ros.org/wiki/xacro">
    <xacro:property name="wheel_radius" value="0.3"/>
    <xacro:macro name="chassis_inertial">
       <inertial>
            <origin xyz="0 0 0" rpy="0 0 0"/>
            <mass value="1"/>
            <!-- https://en.wikipedia.org/wiki/List_of_moments_of_inertia#List_of_3D_inertia_tensors -->
            <inertia
                ixx="0.02" ixy="0.0" ixz="0.0"
                iyy="0.02" iyz="0.0"
                izz="0.0"/>
        </inertial>
    </xacro:macro>

    <material name="grey">
        <color rgba="0.9 0.9 0.9 1.0"/>
    </material>

    <link name="base_link">
        <visual>
            <origin xyz="0 0 0" rpy="0 0 0"/>
            <geometry>
                <box size="0.5 0.1 0.1"/>
            </geometry>
            <material name="grey"/>
        </visual>
        <xacro:chassis_inertial/>
    </link>

    <link name="base_footprint"></link>

    <joint name="base_footprint_joint" type="fixed">
        <parent link="base_link"/>
        <child link="base_footprint"/>
        <origin xyz="0 0 ${-wheel_radius}" rpy="0 0 0"/>
    </joint>

    <xacro:macro name="wheel_macro" params="name radius">
        <link name="${name}">
            <visual>
                <origin xyz="0 0 0" rpy="0 0 0"/>
                <geometry>
                    <cylinder length="0.05" radius="${radius}"/>
                </geometry>
                <material name="grey"/>
            </visual>

            <collision>
                <geometry>
                    <cylinder length="0.2" radius="${radius}"/>
                </geometry>
            </collision>

            <!-- https://en.wikipedia.org/wiki/List_of_moments_of_inertia#List_of_3D_inertia_tensors -->
            <inertial>
                <origin xyz="0 0 0" rpy="0 0 0"/>
                <mass value="1.5"/>
                <inertia
                    ixx="${radius*radius}*0.375" ixy="0.0" ixz="0.0"
                    iyy="${radius*radius}*0.375" iyz="0.0"
                    izz="${radius*radius}*0.125"/>
            </inertial>
        </link>
    </xacro:macro>

    <link name="tube">
        <visual>
            <origin xyz="-0.25 0 0" rpy="0 0 0"/>
            <geometry>
                <box size="0.5 0.1 0.1"/>
            </geometry>
            <material name="grey"/>
        </visual>
        <xacro:chassis_inertial/>
    </link>
    <joint name="tube_joint" type="fixed">
        <parent link="base_link"/>
        <child link="tube"/>
        <origin xyz="0.25 0 0" rpy="0 0 4"/>
    </joint>

    <link name="handle_bar">
        <visual>
            <origin xyz="-0.25 0 0" rpy="0 0 0"/>
            <geometry>
                <box size="0.5 0.1 0.1"/>
            </geometry>
            <material name="grey"/>
        </visual>
        <xacro:chassis_inertial/>
    </link>
    <joint name="handle_bar_joint" type="revolute">
        <parent link="tube"/>
        <child link="handle_bar"/>
        <origin xyz="-0.5 0 0" rpy="0 0 -2"/>
        <limit effort="10" velocity="1.0" lower="-1.4" upper="1.4"/>
        <axis xyz="1 0 0"/>
    </joint>

    <xacro:wheel_macro name="front_wheel" radius="${wheel_radius}"/>
    <joint name="front_wheel_joint" type="continuous">
        <parent link="handle_bar"/>
        <child link="front_wheel"/>
        <origin xyz="-0.5 0 0" rpy="3.14 0 0"/>
        <axis xyz="0 0 1"/>
    </joint>

    <xacro:wheel_macro name="back_wheel" radius="${wheel_radius}"/> 
    <joint name="back_wheel_joint" type="continuous">
        <parent link="base_link"/>
        <child link="back_wheel"/>
        <origin xyz="-0.25 0 0" rpy="3.14 0 0"/>
        <axis xyz="0 0 1"/>
    </joint>

    
    <gazebo reference="base_link">
        <gravity>true</gravity>
        <sensor name="imu_sensor" type="imu">
        <always_on>true</always_on>
        <update_rate>100</update_rate>
        <visualize>true</visualize>
        <topic>__default_topic__</topic>
        <plugin filename="libgazebo_ros_imu_sensor.so" name="imu_plugin">
            <topicName>imu</topicName>
            <bodyName>base_link</bodyName>
            <updateRateHZ>10.0</updateRateHZ>
            <gaussianNoise>0.0</gaussianNoise>
            <xyzOffset>0 0 0</xyzOffset>
            <rpyOffset>0 0 0</rpyOffset>
            <frameName>base_link</frameName>
            <initialOrientationAsReference>true</initialOrientationAsReference>
        </plugin>
        <pose>0 0 0 0 0 0</pose>
        </sensor>
    </gazebo>

    <gazebo>
        <plugin name="gazebo_ros_joint_state_publisher" filename="libgazebo_ros_joint_state_publisher.so">
            <update_rate>100</update_rate>
            <joint_name>front_wheel_joint</joint_name>
            <joint_name>back_wheel_joint</joint_name>
            <joint_name>handle_bar_joint</joint_name>
        </plugin>
    </gazebo>
    

    <gazebo>
        <plugin name="mouse_drive" filename="libmouse_drive.so">
            <back_wheel>back_wheel</back_wheel>
            <handle_bar>handle_bar</handle_bar>
        </plugin>
    </gazebo>
    

    <gazebo reference="base_link">
        <material>Gazebo/Orange</material>
    </gazebo>
    <gazebo reference="handle_bar">
        <material>Gazebo/Orange</material>
    </gazebo>
    <gazebo reference="tube">
        <material>Gazebo/Orange</material>
    </gazebo>

    <gazebo reference="front_wheel">
        <material>Gazebo/Red</material>
    </gazebo>
    <gazebo reference="back_wheel">
        <material>Gazebo/Red</material>
    </gazebo>
</robot>